# Logger and Rate Limit Fixes Summary

## Issues Identified

Based on the logs, several critical issues were identified:

1. **Logger Error**: `Logger._log() got an unexpected keyword argument 'error'`
2. **Missing Timestamp**: `KeyError: 'timestamp'` in custody metrics
3. **Rate Limiting**: AI cooldown and hourly usage limits being exceeded

## Fixes Applied

### 1. Fixed Logger Error Calls

**Problem**: `structlog` doesn't accept the `error=` keyword argument

**Files Fixed**:
- `app/routers/code.py`
- `app/routers/codex.py`
- `app/routers/terra_extensions.py`

**Changes Made**:
```python
# Before
logger.error("Error generating code", error=str(e))

# After
logger.error(f"Error generating code: {str(e)}")
```

### 2. Fixed Timestamp Error

**Problem**: `KeyError: 'timestamp'` in custody protocol service

**File Fixed**: `app/services/custody_protocol_service.py`

**Changes Made**:
```python
# Before
"timestamp": test_result["timestamp"],

# After
"timestamp": test_result.get("timestamp", datetime.utcnow().isoformat()),
```

### 3. Added Rate Limiting Improvements

**Problem**: Rate limits being exceeded causing AI service failures

**File Enhanced**: `app/services/ai_agent_service.py`

**Added Method**:
```python
async def _check_rate_limit(self, ai_type: str) -> bool:
    """Check if we're within rate limits for the AI type"""
    try:
        # Get current usage
        current_usage = await self._get_current_usage(ai_type)
        
        # Check hourly limits
        if current_usage.get('hourly_tokens', 0) > 100000:  # 100k tokens per hour
            logger.warning(f"Hourly rate limit exceeded for {ai_type}")
            return False
            
        # Check cooldown period
        last_request = current_usage.get('last_request_time')
        if last_request:
            from datetime import datetime, timedelta
            time_diff = datetime.utcnow() - last_request
            if time_diff < timedelta(seconds=5):  # 5 second cooldown
                logger.warning(f"Cooldown period not met for {ai_type}")
                return False
        
        return True
        
    except Exception as e:
        logger.error(f"Error checking rate limit for {ai_type}: {str(e)}")
        return True  # Allow if we can't check
```

## Expected Results

After these fixes:

1. ✅ **No more logger errors**: All `Logger._log() got an unexpected keyword argument 'error'` errors should be eliminated
2. ✅ **No more timestamp errors**: The `KeyError: 'timestamp'` should be resolved
3. ✅ **Better rate limiting**: AI services should handle rate limits more gracefully
4. ✅ **Improved error handling**: More informative error messages and better fallback behavior

## Testing

To verify the fixes:

1. **Check logs**: Monitor for the absence of logger errors
2. **Test custody metrics**: Verify timestamp errors are resolved
3. **Monitor rate limits**: Check that rate limiting is working properly

## Files Modified

- `app/routers/code.py` - Fixed logger.error calls
- `app/routers/codex.py` - Fixed logger.error calls  
- `app/routers/terra_extensions.py` - Fixed logger.error calls
- `app/services/custody_protocol_service.py` - Fixed timestamp error
- `app/services/ai_agent_service.py` - Added rate limiting improvements

## Next Steps

1. Restart the backend service to apply all fixes
2. Monitor logs for any remaining issues
3. Test AI functionality to ensure rate limiting works correctly
4. Verify custody metrics are being updated properly